<?xml version='1.0'?>

<robot name="robot" xmlns:xacro="http://www.ros.org/wiki/xacro">

  <link name="body">

  <inertial>
      <mass value="4" />
      <origin xyz="0 0 0"/>
      <inertia ixx="0.001" ixy="0.0" ixz="0.0"
        iyy="0.001" iyz="0.0"
        izz="0.001" />
    </inertial>

    <visual>
     <origin xyz="0 0 0" rpy=" 0 0 0"/>
      <geometry>
       <box size="0.3 0.5 0.1"/>
      </geometry>
   </visual>
   <collision name="collision">
       <geometry>
          <box size="0.3 0.5 0.1"/>
       </geometry>
     </collision>
  </link>

  <joint name="joint1" type="revolute">
    <parent link="body"/>
    <child link="armL1"/>
    <origin xyz="0 -0.2 0.1" rpy="0 0 0" />
    <geometry>
       <sphere radius="0.05"/>
     </geometry>
    <axis xyz="0 0 0" rpy="0 0 0"/>
    <limit effort="1000.0" lower="-3.14" upper="3.14" velocity="1"/>
    <joint_properties damping="1.0"/>
  </joint>

  <link name="armL1">
  <visual>
  <origin rpy="0 0 0" xyz ="0 0 0" />
    <geometry>
      <cylinder length="0.3" radius="0.025" />
    </geometry>
  </visual>
  <collision name="collision">
      <geometry>
         <cylinder length="0.3" radius="0.025" />
      </geometry>
    </collision>
  <inertial>
      <mass value="1" />
      <origin xyz="0 0 0"/>
      <inertia ixx="0.001" ixy="0.0" ixz="0.0"
        iyy="0.001" iyz="0.0"
        izz="0.001" />
    </inertial>
  </link>

  <joint name="joint2" type="revolute">
    <parent link="armL1"/>
    <child link="armL2"/>
    <origin xyz="0 0 0.3" rpy="0 0 0" />
   <geometry>
      <sphere radius="0.025"/>
    </geometry>
    <axis xyz="0 0 0" />
    <limit effort="1000.0" lower="-3.14" upper="3.14" velocity="1"/>
    <joint_properties damping="1.0"/>
  </joint>

  <link name="armL2">
  <visual>
  <origin rpy="0 0 0" xyz ="0 0 0" />
    <geometry>
      <cylinder length="0.3" radius="0.025" />
    </geometry>
  </visual>
  <collision name="collision">
      <geometry>
         <cylinder length="0.3" radius="0.025" />
      </geometry>
    </collision>
  <inertial>
      <mass value="1" />
      <origin xyz="0 0 0"/>
      <inertia ixx="0.001" ixy="0.0" ixz="0.0"
        iyy="0.001" iyz="0.0"
        izz="0.001" />
    </inertial>
  </link>

  <joint name="joint3" type="revolute">
    <parent link="armL2"/>
    <child link="armL3"/>
    <origin xyz="0 0 0.3" rpy="0 0 0" />
    <geometry>
       <sphere radius="0.025"/>
     </geometry>
    <axis xyz="0 0 0" />
    <limit effort="1000.0" lower="-3.14" upper="3.14" velocity="1"/>
    <joint_properties damping="1.0"/>
  </joint>

  <link name="armL3">
  <visual>
  <origin rpy="0 0 0" xyz ="0 0 0" />
    <geometry>
      <cylinder length="0.3" radius="0.025" />
    </geometry>
  </visual>
  <collision name="collision">
      <geometry>
         <cylinder length="0.3" radius="0.025" />
      </geometry>
    </collision>
  <collision>
      <geometry>
        <cylinder length="0.3" radius="0.025" />
      </geometry>
    </collision>
  <inertial>
      <mass value="1" />
      <origin xyz="0 0 0"/>
      <inertia ixx="0.001" ixy="0.0" ixz="0.0"
        iyy="0.001" iyz="0.0"
        izz="0.001" />
    </inertial>
  </link>

  <joint name="joint4" type="revolute">
    <parent link="armL3"/>
    <child link="fork"/>
    <origin xyz="0 0 0.1" rpy="0 0 0" />
    <geometry>
       <sphere radius="0.025"/>
     </geometry>
    <axis xyz="0 0 0" />
    <limit effort="1000.0" lower="-3.14" upper="3.14" velocity="1"/>
    <joint_properties damping="1.0"/>
  </joint>

  <link name="fork">
  <visual>
  <origin rpy="0 0 0" xyz ="0 0.1 0" />
    <geometry>
      <box size="0.1 0.2 0.01" />
    </geometry>
  </visual>
    <collision name="collision">
      <geometry>
           <box size="0.01 0.4 0.01" />
      </geometry>
    </collision>
  <inertial>
      <mass value="1" />
      <origin xyz="-0. 0 0"/>
      <inertia ixx="0.001" ixy="0.0" ixz="0.0"
        iyy="0.001" iyz="0.0"
        izz="0.001" />
    </inertial>
  </link>


  <link name="left_backwheel">

    <collision name="collision">
      <origin xyz="0 0 0" rpy="0 1.5707 1.5707"/>
      <geometry>
        <cylinder radius="0.1" length="0.05"/>
      </geometry>
    </collision>
    <visual name="left_wheel_visual">
      <origin xyz="0 0 0" rpy="0 1.5707 1.5707"/>
      <geometry>
        <cylinder radius="0.1" length="0.05"/>
      </geometry>
    </visual>
    <inertial>
      <origin xyz="0 0 0" rpy="0 1.5707 1.5707"/>
      <mass value="5"/>
      <inertia
        ixx=".1" ixy="0.0" ixz="0.0"
        iyy=".1" iyz="0.0"
        izz=".1"/>
    </inertial>
  </link>

  <link name="left_frontwheel">

    <collision name="collision">
      <origin xyz="0 0 0" rpy="0 1.5707 1.5707"/>
      <geometry>
        <cylinder radius="0.1" length="0.05"/>
      </geometry>
    </collision>
    <visual name="left_wheel_visual">
      <origin xyz="0 0 0" rpy="0 1.5707 1.5707"/>
      <geometry>
        <cylinder radius="0.1" length="0.05"/>
      </geometry>
    </visual>
    <inertial>
      <origin xyz="0 0 0" rpy="0 1.5707 1.5707"/>
      <mass value="5"/>
      <inertia
        ixx=".1" ixy="0.0" ixz="0.0"
        iyy=".1" iyz="0.0"
        izz=".1"/>
    </inertial>
  </link>

  <link name="right_backwheel">

    <collision name="collision">
      <origin xyz="0 0 0" rpy="0 1.5707 1.5707"/>
      <geometry>
        <cylinder radius="0.1" length="0.05"/>
      </geometry>
    </collision>
    <visual name="right_wheel_visual">
      <origin xyz="0 0 0" rpy="0 1.5707 1.5707"/>
      <geometry>
        <cylinder radius="0.1" length="0.05"/>
      </geometry>
    </visual>
    <inertial>
      <origin xyz="0 0 0" rpy="0 1.5707 1.5707"/>
      <mass value="5"/>
      <inertia
        ixx=".1" ixy="0.0" ixz="0.0"
        iyy=".1" iyz="0.0"
        izz=".1"/>
    </inertial>
  </link>

  <link name="right_frontwheel">

    <collision name="collision">
      <origin xyz="0 0 0" rpy="0 1.5707 1.5707"/>
      <geometry>
        <cylinder radius="0.1" length="0.05"/>
      </geometry>
    </collision>
    <visual name="right_wheel_visual">
      <origin xyz="0 0 0" rpy="0 1.5707 1.5707"/>
      <geometry>
        <cylinder radius="0.1" length="0.05"/>
      </geometry>
    </visual>
    <inertial>
      <origin xyz="0 0 0" rpy="0 1.5707 1.5707"/>
      <mass value="5"/>
      <inertia
        ixx=".1" ixy="0.0" ixz="0.0"
        iyy=".1" iyz="0.0"
        izz=".1"/>
    </inertial>
  </link>


  <joint type="continuous" name="left_frontwheel_hinge">
    <origin xyz="-0.15 0.2 0" rpy="0 0 1.5707"/>

    <child link="left_frontwheel"/>
    <parent link="body"/>
    <axis xyz="0 1 0" rpy="0 0 0"/>
    <limit effort="10000" velocity="1000"/>
    <joint_properties damping="1.0" friction="1.0"/>
  </joint>

  <joint type="continuous" name="left_backwheel_hinge">
    <origin xyz="-0.15 -0.2 0" rpy="0 0 1.5707"/>

    <child link="left_backwheel"/>
    <parent link="body"/>
    <axis xyz="0 1 0" rpy="0 0 0"/>
    <limit effort="10000" velocity="1000"/>
    <joint_properties damping="1.0" friction="1.0"/>
  </joint>

  <joint type="continuous" name="right_frontwheel_hinge">
    <origin xyz="0.15 0.2 0" rpy="0 0 1.5707"/>

    <child link="right_frontwheel"/>
    <parent link="body"/>
    <axis xyz="1 0 0" rpy="0 0 0"/>
    <limit effort="10000" velocity="1000"/>
    <joint_properties damping="1.0" friction="1.0"/>
  </joint>

  <joint type="continuous" name="right_backwheel_hinge">
    <origin xyz="0.15 -0.2 0" rpy="0 0 1.5707"/>

    <child link="right_backwheel"/>
    <parent link="body"/>
    <axis xyz="1 0 0" rpy="0 0 0"/>
    <limit effort="10000" velocity="1000"/>
    <joint_properties damping="1.0" friction="1.0"/>
  </joint>



</robot>
